Model DFTB, Test bulk_bcc
Test run at 2018-09-10 11:46

model file: ../../../models/Si/DFTB/model.py
============================================================
Traceback (most recent call last):
  File "run-model-test-cas.py", line 79, in <module>
    sys.stdout.write(open(model_file).read())
IOError: [Errno 2] No such file or directory: '../../../models/Si/DFTB/model.py'
